Workbook
Name FID_1: [1]AGR_Fuels!$A$2

Sheet Region-Time Slices
B4: Regions | E4: TimeSlices
B6: ~BookRegions_Map | E6: ~TimeSlices
B7: BookName | C7: Region | E7: Season | F7: Weekly | G7: DayNite
B8: Model | C8: SAR | E8: 1S | F8: 1MO | G8: 1h | I8: {=_xlfn.TOCOL(_xlfn.ANCHORARRAY(L30))} -> 1S1MO1h | L8: {=TRANSPOSE(F8:F14)} -> 1MO | M8: 2TU | N8: 3WE | O8: 4TH | P8: 5FR | Q8: 6SA | R8: 7SU
E9: 2S | F9: 2TU | G9: 2h | I9: 1S1MO2h | K9: {=E8:E11} -> 1S | L9: {=_xlfn.ANCHORARRAY(K9)&_xlfn.ANCHORARRAY(L8)} -> 1S1MO | M9: 1S2TU | N9: 1S3WE | O9: 1S4TH | P9: 1S5FR | Q9: 1S6SA | R9: 1S7SU
E10: 3S | F10: 3WE | G10: 3h | I10: 1S1MO3h | K10: 2S | L10: 2S1MO | M10: 2S2TU | N10: 2S3WE | O10: 2S4TH | P10: 2S5FR | Q10: 2S6SA | R10: 2S7SU
E11: 4S | F11: 4TH | G11: 4h | I11: 1S1MO4h | K11: 3S | L11: 3S1MO | M11: 3S2TU | N11: 3S3WE | O11: 3S4TH | P11: 3S5FR | Q11: 3S6SA | R11: 3S7SU
E12: 5S | F12: 5FR | G12: 5h | I12: 1S1MO5h | K12: 4S | L12: 4S1MO | M12: 4S2TU | N12: 4S3WE | O12: 4S4TH | P12: 4S5FR | Q12: 4S6SA | R12: 4S7SU
E13: 6S | F13: 6SA | G13: 6h | I13: 1S1MO6h | K13: {=E12:E15} -> 5S | L13: {=_xlfn.ANCHORARRAY(K13)&L8} -> 5S1MO | M13: {=_xlfn.ANCHORARRAY(K13) &M8} -> 5S2TU | N13: {=_xlfn.ANCHORARRAY(K13)&N8} -> 5S3WE | O13: {=_xlfn.ANCHORARRAY(K13)&O8} -> 5S4TH | P13: {=_xlfn.ANCHORARRAY(K13)&P8} -> 5S5FR | Q13: {=_xlfn.ANCHORARRAY(K13)&Q8} -> 5S6SA | R13: {=_xlfn.ANCHORARRAY(K13)&R8} -> 5S7SU
E14: 7S | F14: 7SU | G14: 7h | I14: 1S1MO7h | K14: 6S | L14: 6S1MO | M14: 6S2TU | N14: 6S3WE | O14: 6S4TH | P14: 6S5FR | Q14: 6S6SA | R14: 6S7SU
E15: 8S | G15: 8h | I15: 1S1MO8h | K15: 7S | L15: 7S1MO | M15: 7S2TU | N15: 7S3WE | O15: 7S4TH | P15: 7S5FR | Q15: 7S6SA | R15: 7S7SU
E16: 9S | G16: 9h | I16: 1S1MO9h | K16: 8S | L16: 8S1MO | M16: 8S2TU | N16: 8S3WE | O16: 8S4TH | P16: 8S5FR | Q16: 8S6SA | R16: 8S7SU
E17: 10S | G17: 10h | I17: 1S1MO10h | K17: {=E16:E19} -> 9S | L17: {=_xlfn.ANCHORARRAY(K17)&L8} -> 9S1MO | M17: {=_xlfn.ANCHORARRAY(K17)&M8} -> 9S2TU | N17: {=_xlfn.ANCHORARRAY(K17)&N8} -> 9S3WE | O17: {=_xlfn.ANCHORARRAY(K17)&O8} -> 9S4TH | P17: {=_xlfn.ANCHORARRAY(K17)&P8} -> 9S5FR | Q17: {=_xlfn.ANCHORARRAY(K17)&Q8} -> 9S6SA | R17: {=_xlfn.ANCHORARRAY(K17)&R8} -> 9S7SU
E18: 11S | G18: 11h | I18: 1S1MO11h | K18: 10S | L18: 10S1MO | M18: 10S2TU | N18: 10S3WE | O18: 10S4TH | P18: 10S5FR | Q18: 10S6SA | R18: 10S7SU
E19: S12 | G19: 12h | I19: 1S1MO12h | K19: 11S | L19: 11S1MO | M19: 11S2TU | N19: 11S3WE | O19: 11S4TH | P19: 11S5FR | Q19: 11S6SA | R19: 11S7SU
G20: 13h | I20: 1S1MO13h | K20: S12 | L20: S121MO | M20: S122TU | N20: S123WE | O20: S124TH | P20: S125FR | Q20: S126SA | R20: S127SU
G21: 14h | I21: 1S1MO14h
G22: 15h | I22: 1S1MO15h
G23: 16h | I23: 1S1MO16h
G24: 17h | I24: 1S1MO17h
G25: 18h | I25: 1S1MO18h
G26: 19h | I26: 1S1MO19h
G27: 20h | I27: 1S1MO20h
G28: 21h | I28: 1S1MO21h
G29: 22h | I29: 1S1MO22h | L29: {=TRANSPOSE(G8:G31)} -> 1h | M29: 2h | N29: 3h | O29: 4h | P29: 5h | Q29: 6h | R29: 7h | S29: 8h | T29: 9h | U29: 10h | V29: 11h | W29: 12h | X29: 13h | Y29: 14h | Z29: 15h | AA29: 16h | AB29: 17h | AC29: 18h | AD29: 19h | AE29: 20h | AF29: 21h | AG29: 22h | AH29: 23h | AI29: 24h
G30: 23h | I30: 1S1MO23h | K30: {=_xlfn.TOCOL(_xlfn.ANCHORARRAY(L9))} -> 1S1MO | L30: {=_xlfn.ANCHORARRAY(K30)&_xlfn.ANCHORARRAY(L29)} -> 1S1MO1h | M30: 1S1MO2h | N30: 1S1MO3h | O30: 1S1MO4h | P30: 1S1MO5h | Q30: 1S1MO6h | R30: 1S1MO7h | S30: 1S1MO8h | T30: 1S1MO9h | U30: 1S1MO10h | V30: 1S1MO11h | W30: 1S1MO12h | X30: 1S1MO13h | Y30: 1S1MO14h | Z30: 1S1MO15h | AA30: 1S1MO16h | AB30: 1S1MO17h | AC30: 1S1MO18h | AD30: 1S1MO19h | AE30: 1S1MO20h | AF30: 1S1MO21h | AG30: 1S1MO22h | AH30: 1S1MO23h | AI30: 1S1MO24h
G31: 24h | I31: 1S1MO24h | K31: 1S2TU | L31: 1S2TU1h | M31: 1S2TU2h | N31: 1S2TU3h | O31: 1S2TU4h | P31: 1S2TU5h | Q31: 1S2TU6h | R31: 1S2TU7h | S31: 1S2TU8h | T31: 1S2TU9h | U31: 1S2TU10h | V31: 1S2TU11h | W31: 1S2TU12h | X31: 1S2TU13h | Y31: 1S2TU14h | Z31: 1S2TU15h | AA31: 1S2TU16h | AB31: 1S2TU17h | AC31: 1S2TU18h | AD31: 1S2TU19h | AE31: 1S2TU20h | AF31: 1S2TU21h | AG31: 1S2TU22h | AH31: 1S2TU23h | AI31: 1S2TU24h
I32: 1S2TU1h | K32: 1S3WE | L32: 1S3WE1h | M32: 1S3WE2h | N32: 1S3WE3h | O32: 1S3WE4h | P32: 1S3WE5h | Q32: 1S3WE6h | R32: 1S3WE7h | S32: 1S3WE8h | T32: 1S3WE9h | U32: 1S3WE10h | V32: 1S3WE11h | W32: 1S3WE12h | X32: 1S3WE13h | Y32: 1S3WE14h | Z32: 1S3WE15h | AA32: 1S3WE16h | AB32: 1S3WE17h | AC32: 1S3WE18h | AD32: 1S3WE19h | AE32: 1S3WE20h | AF32: 1S3WE21h | AG32: 1S3WE22h | AH32: 1S3WE23h | AI32: 1S3WE24h
I33: 1S2TU2h | K33: 1S4TH | L33: 1S4TH1h | M33: 1S4TH2h | N33: 1S4TH3h | O33: 1S4TH4h | P33: 1S4TH5h | Q33: 1S4TH6h | R33: 1S4TH7h | S33: 1S4TH8h | T33: 1S4TH9h | U33: 1S4TH10h | V33: 1S4TH11h | W33: 1S4TH12h | X33: 1S4TH13h | Y33: 1S4TH14h | Z33: 1S4TH15h | AA33: 1S4TH16h | AB33: 1S4TH17h | AC33: 1S4TH18h | AD33: 1S4TH19h | AE33: 1S4TH20h | AF33: 1S4TH21h | AG33: 1S4TH22h | AH33: 1S4TH23h | AI33: 1S4TH24h
I34: 1S2TU3h | K34: 1S5FR | L34: 1S5FR1h | M34: 1S5FR2h | N34: 1S5FR3h | O34: 1S5FR4h | P34: 1S5FR5h | Q34: 1S5FR6h | R34: 1S5FR7h | S34: 1S5FR8h | T34: 1S5FR9h | U34: 1S5FR10h | V34: 1S5FR11h | W34: 1S5FR12h | X34: 1S5FR13h | Y34: 1S5FR14h | Z34: 1S5FR15h | AA34: 1S5FR16h | AB34: 1S5FR17h | AC34: 1S5FR18h | AD34: 1S5FR19h | AE34: 1S5FR20h | AF34: 1S5FR21h | AG34: 1S5FR22h | AH34: 1S5FR23h | AI34: 1S5FR24h
I35: 1S2TU4h | K35: 1S6SA | L35: 1S6SA1h | M35: 1S6SA2h | N35: 1S6SA3h | O35: 1S6SA4h | P35: 1S6SA5h | Q35: 1S6SA6h | R35: 1S6SA7h | S35: 1S6SA8h | T35: 1S6SA9h | U35: 1S6SA10h | V35: 1S6SA11h | W35: 1S6SA12h | X35: 1S6SA13h | Y35: 1S6SA14h | Z35: 1S6SA15h | AA35: 1S6SA16h | AB35: 1S6SA17h | AC35: 1S6SA18h | AD35: 1S6SA19h | AE35: 1S6SA20h | AF35: 1S6SA21h | AG35: 1S6SA22h | AH35: 1S6SA23h | AI35: 1S6SA24h
I36: 1S2TU5h | K36: 1S7SU | L36: 1S7SU1h | M36: 1S7SU2h | N36: 1S7SU3h | O36: 1S7SU4h | P36: 1S7SU5h | Q36: 1S7SU6h | R36: 1S7SU7h | S36: 1S7SU8h | T36: 1S7SU9h | U36: 1S7SU10h | V36: 1S7SU11h | W36: 1S7SU12h | X36: 1S7SU13h | Y36: 1S7SU14h | Z36: 1S7SU15h | AA36: 1S7SU16h | AB36: 1S7SU17h | AC36: 1S7SU18h | AD36: 1S7SU19h | AE36: 1S7SU20h | AF36: 1S7SU21h | AG36: 1S7SU22h | AH36: 1S7SU23h | AI36: 1S7SU24h
I37: 1S2TU6h | K37: 2S1MO | L37: 2S1MO1h | M37: 2S1MO2h | N37: 2S1MO3h | O37: 2S1MO4h | P37: 2S1MO5h | Q37: 2S1MO6h | R37: 2S1MO7h | S37: 2S1MO8h | T37: 2S1MO9h | U37: 2S1MO10h | V37: 2S1MO11h | W37: 2S1MO12h | X37: 2S1MO13h | Y37: 2S1MO14h | Z37: 2S1MO15h | AA37: 2S1MO16h | AB37: 2S1MO17h | AC37: 2S1MO18h | AD37: 2S1MO19h | AE37: 2S1MO20h | AF37: 2S1MO21h | AG37: 2S1MO22h | AH37: 2S1MO23h | AI37: 2S1MO24h
I38: 1S2TU7h | K38: 2S2TU | L38: 2S2TU1h | M38: 2S2TU2h | N38: 2S2TU3h | O38: 2S2TU4h | P38: 2S2TU5h | Q38: 2S2TU6h | R38: 2S2TU7h | S38: 2S2TU8h | T38: 2S2TU9h | U38: 2S2TU10h | V38: 2S2TU11h | W38: 2S2TU12h | X38: 2S2TU13h | Y38: 2S2TU14h | Z38: 2S2TU15h | AA38: 2S2TU16h | AB38: 2S2TU17h | AC38: 2S2TU18h | AD38: 2S2TU19h | AE38: 2S2TU20h | AF38: 2S2TU21h | AG38: 2S2TU22h | AH38: 2S2TU23h | AI38: 2S2TU24h
I39: 1S2TU8h | K39: 2S3WE | L39: 2S3WE1h | M39: 2S3WE2h | N39: 2S3WE3h | O39: 2S3WE4h | P39: 2S3WE5h | Q39: 2S3WE6h | R39: 2S3WE7h | S39: 2S3WE8h | T39: 2S3WE9h | U39: 2S3WE10h | V39: 2S3WE11h | W39: 2S3WE12h | X39: 2S3WE13h | Y39: 2S3WE14h | Z39: 2S3WE15h | AA39: 2S3WE16h | AB39: 2S3WE17h | AC39: 2S3WE18h | AD39: 2S3WE19h | AE39: 2S3WE20h | AF39: 2S3WE21h | AG39: 2S3WE22h | AH39: 2S3WE23h | AI39: 2S3WE24h
I40: 1S2TU9h | K40: 2S4TH | L40: 2S4TH1h | M40: 2S4TH2h | N40: 2S4TH3h | O40: 2S4TH4h | P40: 2S4TH5h | Q40: 2S4TH6h | R40: 2S4TH7h | S40: 2S4TH8h | T40: 2S4TH9h | U40: 2S4TH10h | V40: 2S4TH11h | W40: 2S4TH12h | X40: 2S4TH13h | Y40: 2S4TH14h | Z40: 2S4TH15h | AA40: 2S4TH16h | AB40: 2S4TH17h | AC40: 2S4TH18h | AD40: 2S4TH19h | AE40: 2S4TH20h | AF40: 2S4TH21h | AG40: 2S4TH22h | AH40: 2S4TH23h | AI40: 2S4TH24h
I41: 1S2TU10h | K41: 2S5FR | L41: 2S5FR1h | M41: 2S5FR2h | N41: 2S5FR3h | O41: 2S5FR4h | P41: 2S5FR5h | Q41: 2S5FR6h | R41: 2S5FR7h | S41: 2S5FR8h | T41: 2S5FR9h | U41: 2S5FR10h | V41: 2S5FR11h | W41: 2S5FR12h | X41: 2S5FR13h | Y41: 2S5FR14h | Z41: 2S5FR15h | AA41: 2S5FR16h | AB41: 2S5FR17h | AC41: 2S5FR18h | AD41: 2S5FR19h | AE41: 2S5FR20h | AF41: 2S5FR21h | AG41: 2S5FR22h | AH41: 2S5FR23h | AI41: 2S5FR24h
I42: 1S2TU11h | K42: 2S6SA | L42: 2S6SA1h | M42: 2S6SA2h | N42: 2S6SA3h | O42: 2S6SA4h | P42: 2S6SA5h | Q42: 2S6SA6h | R42: 2S6SA7h | S42: 2S6SA8h | T42: 2S6SA9h | U42: 2S6SA10h | V42: 2S6SA11h | W42: 2S6SA12h | X42: 2S6SA13h | Y42: 2S6SA14h | Z42: 2S6SA15h | AA42: 2S6SA16h | AB42: 2S6SA17h | AC42: 2S6SA18h | AD42: 2S6SA19h | AE42: 2S6SA20h | AF42: 2S6SA21h | AG42: 2S6SA22h | AH42: 2S6SA23h | AI42: 2S6SA24h
I43: 1S2TU12h | K43: 2S7SU | L43: 2S7SU1h | M43: 2S7SU2h | N43: 2S7SU3h | O43: 2S7SU4h | P43: 2S7SU5h | Q43: 2S7SU6h | R43: 2S7SU7h | S43: 2S7SU8h | T43: 2S7SU9h | U43: 2S7SU10h | V43: 2S7SU11h | W43: 2S7SU12h | X43: 2S7SU13h | Y43: 2S7SU14h | Z43: 2S7SU15h | AA43: 2S7SU16h | AB43: 2S7SU17h | AC43: 2S7SU18h | AD43: 2S7SU19h | AE43: 2S7SU20h | AF43: 2S7SU21h | AG43: 2S7SU22h | AH43: 2S7SU23h | AI43: 2S7SU24h
... I57: 1S3WE2h | K57: 4S7SU | L57: 4S7SU1h | M57: 4S7SU2h | N57: 4S7SU3h | O57: 4S7SU4h | P57: 4S7SU5h | Q57: 4S7SU6h | R57: 4S7SU7h | S57: 4S7SU8h | T57: 4S7SU9h | U57: 4S7SU10h | V57: 4S7SU11h | W57: 4S7SU12h | X57: 4S7SU13h | Y57: 4S7SU14h | Z57: 4S7SU15h | AA57: 4S7SU16h | AB57: 4S7SU17h | AC57: 4S7SU18h | AD57: 4S7SU19h | AE57: 4S7SU20h | AF57: 4S7SU21h | AG57: 4S7SU22h | AH57: 4S7SU23h | AI57: 4S7SU24h
...

Sheet TimePeriods
B4: Start Year
B6: ~StartYear
B7: 2023
B13: Period definition | E13: Active period definition
B15: ~TimePeriods | E15: ~ActivePDef
B16: Pdef-1 | E16: Pdef-1
B17: 1
B18: 4
B19: 5
B20: 5
B21: 5
B22: 5
B23: 5
B25: 5

Sheet Interpol_Extrapol_Defaults
B4: Global interpolation settings
B6: ~TFM_MIG
B7: LimType | C7: Attribute | D7: Year2 | E7: AllRegions | F7: Pset_PN
B8: UP | C8: ACT_BND | D8: 0 | E8: 5
B10: FX | C10: AFA | D10: 0 | E10: 1
B11: UP | C11: Share-O | D11: 0 | E11: 5
B12: UP | C12: Share-I | D12: 0 | E12: 5
B14: Dummy Import Prices
B16: ~TFM_UPD
B17: Attribute | C17: AllRegions | D17: Pset_Set | E17: Pset_PN
B18: ACTCOST | C18: 3333 | D18: IRE | E18: IMP*Z
B19: ACTCOST | C19: 8888 | D19: IRE | E19: IMPDEMZ

Sheet Constants
B3: * Definizioni delle costanti nel modello
B5: ~TFM_INS
B6: TimeSlice | C6: LimType | D6: Attribute | E6: Year | F6: Other_Indexes | G6: AllRegions | H6: Cset_CN
D7: G_DYEAR | G7: 2023
D8: Discount | G8: 0.07
D9: G_DYEAR | G9: 2023
D10: G_CYCLE | F10: DAYNITE | G10: 12
B11: \I:
B12: ='Region-Time Slices'!I8 -> 1S1MO1h | D12: YRFR | G12: =1/2016 -> 0.00049603175
B13: ='Region-Time Slices'!I9 -> 1S1MO2h | D13: YRFR | G13: =1/2016 -> 0.00049603175
B14: ='Region-Time Slices'!I10 -> 1S1MO3h | D14: YRFR | G14: =1/2016 -> 0.00049603175
B15: ='Region-Time Slices'!I11 -> 1S1MO4h | D15: YRFR | G15: =1/2016 -> 0.00049603175
B16: ='Region-Time Slices'!I12 -> 1S1MO5h | D16: YRFR | G16: =1/2016 -> 0.00049603175
B17: ='Region-Time Slices'!I13 -> 1S1MO6h | D17: YRFR | G17: =1/2016 -> 0.00049603175
B18: ='Region-Time Slices'!I14 -> 1S1MO7h | D18: YRFR | G18: =1/2016 -> 0.00049603175
B19: ='Region-Time Slices'!I15 -> 1S1MO8h | D19: YRFR | G19: =1/2016 -> 0.00049603175
B20: ='Region-Time Slices'!I16 -> 1S1MO9h | D20: YRFR | G20: =1/2016 -> 0.00049603175
B21: ='Region-Time Slices'!I17 -> 1S1MO10h | D21: YRFR | G21: =1/2016 -> 0.00049603175
B22: ='Region-Time Slices'!I18 -> 1S1MO11h | D22: YRFR | G22: =1/2016 -> 0.00049603175
B23: ='Region-Time Slices'!I19 -> 1S1MO12h | D23: YRFR | G23: =1/2016 -> 0.00049603175
... B2027: ='Region-Time Slices'!I2023 -> S127SU24h | D2027: YRFR | G2027: =1/2016 -> 0.00049603175

Sheet Defaults
B2: * Currencies | D2: * Default Units
B4: ~Currencies | D4: ~DefUnits
B5: Currency | D5: Option | E5: PRI | F5: ELC | G5: IND | H5: RCA | I5: TRA
B6: MPLN | D6: Process_ActUnit | E6: PJ | F6: PJ | G6: PJ | H6: PJ | I6: kPk
B7: MEuro | D7: Process_CapUnit | E7: PJa | F7: GW | G7: GW | H7: PJa | I7: 000_Units
D8: Commodity_Unit | E8: PJ | F8: PJ | G8: PJ | H8: PJ | I8: kPk
B11: * Unit Conversion
B13: ~UnitConversion
B14: from_unit | C14: to_unit | D14: multiplier
B15: QBtu | C15: PJ | D15: 1055.55
B16: TWh | C16: PJ | D16: 3.6
B17: Mt | C17: Kt | D17: 1000
B18: B Euro | C18: M Euro | D18: 1000
B19: TBtu | C19: PJ | D19: 1.05555
B20: ktoe | C20: PJ | D20: 0.041868
B21: mtoe | C21: PJ | D21: 41.868
B22: Gwh | C22: PJ | D22: 0.0036
B23: Gt | C23: Kt | D23: 1000000
B24: bEur | C24: mEur | D24: 1000
B25: Eur per bbl | C25: Eur per GJ | D25: 0.153846
B26: Eur per ton | C26: mEur per kt | D26: -0.001
... B30: Cents per Kwh | C30: Eur per GJ | D30: 2.777777
B31: PJ | C31: TWh | D31: =1/3.6 -> 0.27777778
B32: PJ | C32: PJ | D32: 1
B33: MPLN | C33: MEuro | D33: 4.5

Sheet Reporting
B2: ~TFM_INS
B3: Attribute | C3: Other_Indexes | D3: AllRegions
B4: RPT_OPT | C4: FLO~3 | D4: 1
